Workbook

Sheet Weekly
A1: Build | B1: Room | C1: Task | D1: Days | E1: Worker | F1: Instructions | G1: Equipment | H1: Mon | I1: Tue | J1: Wed | K1: Thu | L1: Fri
A2: SB | B2: 100 | C2: Empty Trash Small | D2: 4 | E2: Ryan | F2: {=INDEX(Tasks!$B:$B, MATCH(C2, Tasks!$A:$A, 0))} -> Empty trash being careful of leaking bags. | G2: {=_xludf.LET( _xlpm.task,$C2, _xlpm.r, _xludf.XMATCH(_xlpm.task, Tasks!$A:$A, 0), _xlpm.equip, Tasks!$C$1:$Y$1, _xlpm.flags, INDEX(Tasks!$C:$Y, _xlpm.r, 0), _xlpm.needed, _xlws.FILTER(_xlpm.equip, LOWER(_xlpm.flags)="x"), IFERROR("Equipment: " & _xludf.TEXTJOIN(", ", TRUE, _xlpm.needed), "Equipment: ") )} -> #NAME? | H2: =IFERROR(IF(FIND("1",$D2),H$1,""),"") | I2: =IFERROR(IF(FIND("2",$D2),I$1,""),"") | J2: =IFERROR(IF(FIND("3",$D2),J$1,""),"") | K2: =IFERROR(IF(FIND("4",$D2),K$1,""),"") -> Thu | L2: =IFERROR(IF(FIND("5",$D2),L$1,""),"") | M2: {=_xludf.CONCAT("every ",_xludf.TEXTJOIN(", ", TRUE, IF(H2:L2<>"", H2:L2, "")))} -> #NAME?
A3: SB | B3: 100 | C3: Vacuum Light Traffic | D3: 1 | E3: Ryan | F3: {=INDEX(Tasks!$B:$B, MATCH(C3, Tasks!$A:$A, 0))} -> Use Backpack Vacuum. | G3: {=_xludf.LET( _xlpm.task,$C3, _xlpm.r, _xludf.XMATCH(_xlpm.task, Tasks!$A:$A, 0), _xlpm.equip, Tasks!$C$1:$Y$1, _xlpm.flags, INDEX(Tasks!$C:$Y, _xlpm.r, 0), _xlpm.needed, _xlws.FILTER(_xlpm.equip, LOWER(_xlpm.flags)="x"), IFERROR("Equipment: " & _xludf.TEXTJOIN(", ", TRUE, _xlpm.needed), "Equipment: ") )} -> #NAME? | H3: =IFERROR(IF(FIND("1",$D3),H$1,""),"") -> Mon | I3: =IFERROR(IF(FIND("2",$D3),I$1,""),"") | J3: =IFERROR(IF(FIND("3",$D3),J$1,""),"") | K3: =IFERROR(IF(FIND("4",$D3),K$1,""),"") | L3: =IFERROR(IF(FIND("5",$D3),L$1,""),"") | M3: {=_xludf.CONCAT("every ",_xludf.TEXTJOIN(", ", TRUE, IF(H3:L3<>"", H3:L3, "")))} -> #NAME?
A4: SB | B4: 100 | C4: Wipe down Tables | D4: 2 | E4: Ryan | F4: {=INDEX(Tasks!$B:$B, MATCH(C4, Tasks!$A:$A, 0))} -> Spray with 2in1, wipe with Paper Towel. | G4: {=_xludf.LET( _xlpm.task,$C4, _xlpm.r, _xludf.XMATCH(_xlpm.task, Tasks!$A:$A, 0), _xlpm.equip, Tasks!$C$1:$Y$1, _xlpm.flags, INDEX(Tasks!$C:$Y, _xlpm.r, 0), _xlpm.needed, _xlws.FILTER(_xlpm.equip, LOWER(_xlpm.flags)="x"), IFERROR("Equipment: " & _xludf.TEXTJOIN(", ", TRUE, _xlpm.needed), "Equipment: ") )} -> #NAME? | H4: =IFERROR(IF(FIND("1",$D4),H$1,""),"") | I4: =IFERROR(IF(FIND("2",$D4),I$1,""),"") -> Tue | J4: =IFERROR(IF(FIND("3",$D4),J$1,""),"") | K4: =IFERROR(IF(FIND("4",$D4),K$1,""),"") | L4: =IFERROR(IF(FIND("5",$D4),L$1,""),"") | M4: {=_xludf.CONCAT("every ",_xludf.TEXTJOIN(", ", TRUE, IF(H4:L4<>"", H4:L4, "")))} -> #NAME?
A5: SB | B5: 101 | C5: Empty Trash Small | D5: 2 | E5: Ryan | F5: {=INDEX(Tasks!$B:$B, MATCH(C5, Tasks!$A:$A, 0))} -> Empty trash being careful of leaking bags. | G5: {=_xludf.LET( _xlpm.task,$C5, _xlpm.r, _xludf.XMATCH(_xlpm.task, Tasks!$A:$A, 0), _xlpm.equip, Tasks!$C$1:$Y$1, _xlpm.flags, INDEX(Tasks!$C:$Y, _xlpm.r, 0), _xlpm.needed, _xlws.FILTER(_xlpm.equip, LOWER(_xlpm.flags)="x"), IFERROR("Equipment: " & _xludf.TEXTJOIN(", ", TRUE, _xlpm.needed), "Equipment: ") )} -> #NAME? | H5: =IFERROR(IF(FIND("1",$D5),H$1,""),"") | I5: =IFERROR(IF(FIND("2",$D5),I$1,""),"") -> Tue | J5: =IFERROR(IF(FIND("3",$D5),J$1,""),"") | K5: =IFERROR(IF(FIND("4",$D5),K$1,""),"") | L5: =IFERROR(IF(FIND("5",$D5),L$1,""),"") | M5: {=_xludf.CONCAT("every ",_xludf.TEXTJOIN(", ", TRUE, IF(H5:L5<>"", H5:L5, "")))} -> #NAME?
A6: SB | B6: 101 | C6: Vacuum Light Traffic | D6: 1 | E6: Ryan | F6: {=INDEX(Tasks!$B:$B, MATCH(C6, Tasks!$A:$A, 0))} -> Use Backpack Vacuum. | G6: {=_xludf.LET( _xlpm.task,$C6, _xlpm.r, _xludf.XMATCH(_xlpm.task, Tasks!$A:$A, 0), _xlpm.equip, Tasks!$C$1:$Y$1, _xlpm.flags, INDEX(Tasks!$C:$Y, _xlpm.r, 0), _xlpm.needed, _xlws.FILTER(_xlpm.equip, LOWER(_xlpm.flags)="x"), IFERROR("Equipment: " & _xludf.TEXTJOIN(", ", TRUE, _xlpm.needed), "Equipment: ") )} -> #NAME? | H6: =IFERROR(IF(FIND("1",$D6),H$1,""),"") -> Mon | I6: =IFERROR(IF(FIND("2",$D6),I$1,""),"") | J6: =IFERROR(IF(FIND("3",$D6),J$1,""),"") | K6: =IFERROR(IF(FIND("4",$D6),K$1,""),"") | L6: =IFERROR(IF(FIND("5",$D6),L$1,""),"") | M6: {=_xludf.CONCAT("every ",_xludf.TEXTJOIN(", ", TRUE, IF(H6:L6<>"", H6:L6, "")))} -> #NAME?
A7: SB | B7: 101 | C7: Wipe down Counters | D7: 2 | E7: Ryan | F7: {=INDEX(Tasks!$B:$B, MATCH(C7, Tasks!$A:$A, 0))} -> Spray with 2in1, wipe with Paper Towel. | G7: {=_xludf.LET( _xlpm.task,$C7, _xlpm.r, _xludf.XMATCH(_xlpm.task, Tasks!$A:$A, 0), _xlpm.equip, Tasks!$C$1:$Y$1, _xlpm.flags, INDEX(Tasks!$C:$Y, _xlpm.r, 0), _xlpm.needed, _xlws.FILTER(_xlpm.equip, LOWER(_xlpm.flags)="x"), IFERROR("Equipment: " & _xludf.TEXTJOIN(", ", TRUE, _xlpm.needed), "Equipment: ") )} -> #NAME? | H7: =IFERROR(IF(FIND("1",$D7),H$1,""),"") | I7: =IFERROR(IF(FIND("2",$D7),I$1,""),"") -> Tue | J7: =IFERROR(IF(FIND("3",$D7),J$1,""),"") | K7: =IFERROR(IF(FIND("4",$D7),K$1,""),"") | L7: =IFERROR(IF(FIND("5",$D7),L$1,""),"") | M7: {=_xludf.CONCAT("every ",_xludf.TEXTJOIN(", ", TRUE, IF(H7:L7<>"", H7:L7, "")))} -> #NAME?
A8: SB | B8: 101 | C8: Wipe down Tables | D8: 2 | E8: Ryan | F8: {=INDEX(Tasks!$B:$B, MATCH(C8, Tasks!$A:$A, 0))} -> Spray with 2in1, wipe with Paper Towel. | G8: {=_xludf.LET( _xlpm.task,$C8, _xlpm.r, _xludf.XMATCH(_xlpm.task, Tasks!$A:$A, 0), _xlpm.equip, Tasks!$C$1:$Y$1, _xlpm.flags, INDEX(Tasks!$C:$Y, _xlpm.r, 0), _xlpm.needed, _xlws.FILTER(_xlpm.equip, LOWER(_xlpm.flags)="x"), IFERROR("Equipment: " & _xludf.TEXTJOIN(", ", TRUE, _xlpm.needed), "Equipment: ") )} -> #NAME? | H8: =IFERROR(IF(FIND("1",$D8),H$1,""),"") | I8: =IFERROR(IF(FIND("2",$D8),I$1,""),"") -> Tue | J8: =IFERROR(IF(FIND("3",$D8),J$1,""),"") | K8: =IFERROR(IF(FIND("4",$D8),K$1,""),"") | L8: =IFERROR(IF(FIND("5",$D8),L$1,""),"") | M8: {=_xludf.CONCAT("every ",_xludf.TEXTJOIN(", ", TRUE, IF(H8:L8<>"", H8:L8, "")))} -> #NAME?
A9: SB | B9: 102 | C9: Empty Trash Small | D9: 4 | E9: Ryan | F9: {=INDEX(Tasks!$B:$B, MATCH(C9, Tasks!$A:$A, 0))} -> Empty trash being careful of leaking bags. | G9: {=_xludf.LET( _xlpm.task,$C9, _xlpm.r, _xludf.XMATCH(_xlpm.task, Tasks!$A:$A, 0), _xlpm.equip, Tasks!$C$1:$Y$1, _xlpm.flags, INDEX(Tasks!$C:$Y, _xlpm.r, 0), _xlpm.needed, _xlws.FILTER(_xlpm.equip, LOWER(_xlpm.flags)="x"), IFERROR("Equipment: " & _xludf.TEXTJOIN(", ", TRUE, _xlpm.needed), "Equipment: ") )} -> #NAME? | H9: =IFERROR(IF(FIND("1",$D9),H$1,""),"") | I9: =IFERROR(IF(FIND("2",$D9),I$1,""),"") | J9: =IFERROR(IF(FIND("3",$D9),J$1,""),"") | K9: =IFERROR(IF(FIND("4",$D9),K$1,""),"") -> Thu | L9: =IFERROR(IF(FIND("5",$D9),L$1,""),"") | M9: {=_xludf.CONCAT("every ",_xludf.TEXTJOIN(", ", TRUE, IF(H9:L9<>"", H9:L9, "")))} -> #NAME?
A10: SB | B10: 102 | C10: Vacuum Light Traffic | D10: 1 | E10: Ryan | F10: {=INDEX(Tasks!$B:$B, MATCH(C10, Tasks!$A:$A, 0))} -> Use Backpack Vacuum. | G10: {=_xludf.LET( _xlpm.task,$C10, _xlpm.r, _xludf.XMATCH(_xlpm.task, Tasks!$A:$A, 0), _xlpm.equip, Tasks!$C$1:$Y$1, _xlpm.flags, INDEX(Tasks!$C:$Y, _xlpm.r, 0), _xlpm.needed, _xlws.FILTER(_xlpm.equip, LOWER(_xlpm.flags)="x"), IFERROR("Equipment: " & _xludf.TEXTJOIN(", ", TRUE, _xlpm.needed), "Equipment: ") )} -> #NAME? | H10: =IFERROR(IF(FIND("1",$D10),H$1,""),"") -> Mon | I10: =IFERROR(IF(FIND("2",$D10),I$1,""),"") | J10: =IFERROR(IF(FIND("3",$D10),J$1,""),"") | K10: =IFERROR(IF(FIND("4",$D10),K$1,""),"") | L10: =IFERROR(IF(FIND("5",$D10),L$1,""),"") | M10: {=_xludf.CONCAT("every ",_xludf.TEXTJOIN(", ", TRUE, IF(H10:L10<>"", H10:L10, "")))} -> #NAME?
A11: SB | B11: 102 | C11: Wipe down Counters | D11: 2 | E11: Ryan | F11: {=INDEX(Tasks!$B:$B, MATCH(C11, Tasks!$A:$A, 0))} -> Spray with 2in1, wipe with Paper Towel. | G11: {=_xludf.LET( _xlpm.task,$C11, _xlpm.r, _xludf.XMATCH(_xlpm.task, Tasks!$A:$A, 0), _xlpm.equip, Tasks!$C$1:$Y$1, _xlpm.flags, INDEX(Tasks!$C:$Y, _xlpm.r, 0), _xlpm.needed, _xlws.FILTER(_xlpm.equip, LOWER(_xlpm.flags)="x"), IFERROR("Equipment: " & _xludf.TEXTJOIN(", ", TRUE, _xlpm.needed), "Equipment: ") )} -> #NAME? | H11: =IFERROR(IF(FIND("1",$D11),H$1,""),"") | I11: =IFERROR(IF(FIND("2",$D11),I$1,""),"") -> Tue | J11: =IFERROR(IF(FIND("3",$D11),J$1,""),"") | K11: =IFERROR(IF(FIND("4",$D11),K$1,""),"") | L11: =IFERROR(IF(FIND("5",$D11),L$1,""),"") | M11: {=_xludf.CONCAT("every ",_xludf.TEXTJOIN(", ", TRUE, IF(H11:L11<>"", H11:L11, "")))} -> #NAME?
A12: SB | B12: 102 | C12: Wipe down Sink | D12: 2 | E12: Ryan | F12: {=INDEX(Tasks!$B:$B, MATCH(C12, Tasks!$A:$A, 0))} -> Spray with 2in1, wipe with Paper Towel. | G12: {=_xludf.LET( _xlpm.task,$C12, _xlpm.r, _xludf.XMATCH(_xlpm.task, Tasks!$A:$A, 0), _xlpm.equip, Tasks!$C$1:$Y$1, _xlpm.flags, INDEX(Tasks!$C:$Y, _xlpm.r, 0), _xlpm.needed, _xlws.FILTER(_xlpm.equip, LOWER(_xlpm.flags)="x"), IFERROR("Equipment: " & _xludf.TEXTJOIN(", ", TRUE, _xlpm.needed), "Equipment: ") )} -> #NAME? | H12: =IFERROR(IF(FIND("1",$D12),H$1,""),"") | I12: =IFERROR(IF(FIND("2",$D12),I$1,""),"") -> Tue | J12: =IFERROR(IF(FIND("3",$D12),J$1,""),"") | K12: =IFERROR(IF(FIND("4",$D12),K$1,""),"") | L12: =IFERROR(IF(FIND("5",$D12),L$1,""),"") | M12: {=_xludf.CONCAT("every ",_xludf.TEXTJOIN(", ", TRUE, IF(H12:L12<>"", H12:L12, "")))} -> #NAME?
A13: SB | B13: 102 | C13: Wipe down Tables | D13: 2 | E13: Ryan | F13: {=INDEX(Tasks!$B:$B, MATCH(C13, Tasks!$A:$A, 0))} -> Spray with 2in1, wipe with Paper Towel. | G13: {=_xludf.LET( _xlpm.task,$C13, _xlpm.r, _xludf.XMATCH(_xlpm.task, Tasks!$A:$A, 0), _xlpm.equip, Tasks!$C$1:$Y$1, _xlpm.flags, INDEX(Tasks!$C:$Y, _xlpm.r, 0), _xlpm.needed, _xlws.FILTER(_xlpm.equip, LOWER(_xlpm.flags)="x"), IFERROR("Equipment: " & _xludf.TEXTJOIN(", ", TRUE, _xlpm.needed), "Equipment: ") )} -> #NAME? | H13: =IFERROR(IF(FIND("1",$D13),H$1,""),"") | I13: =IFERROR(IF(FIND("2",$D13),I$1,""),"") -> Tue | J13: =IFERROR(IF(FIND("3",$D13),J$1,""),"") | K13: =IFERROR(IF(FIND("4",$D13),K$1,""),"") | L13: =IFERROR(IF(FIND("5",$D13),L$1,""),"") | M13: {=_xludf.CONCAT("every ",_xludf.TEXTJOIN(", ", TRUE, IF(H13:L13<>"", H13:L13, "")))} -> #NAME?
... A46: SB | B46: 205 | C46: Wipe down Tables | D46: 3 | E46: Ryan | F46: {=INDEX(Tasks!$B:$B, MATCH(C46, Tasks!$A:$A, 0))} -> Spray with 2in1, wipe with Paper Towel. | G46: {=_xludf.LET( _xlpm.task,$C46, _xlpm.r, _xludf.XMATCH(_xlpm.task, Tasks!$A:$A, 0), _xlpm.equip, Tasks!$C$1:$Y$1, _xlpm.flags, INDEX(Tasks!$C:$Y, _xlpm.r, 0), _xlpm.needed, _xlws.FILTER(_xlpm.equip, LOWER(_xlpm.flags)="x"), IFERROR("Equipment: " & _xludf.TEXTJOIN(", ", TRUE, _xlpm.needed), "Equipment: ") )} -> #NAME? | H46: =IFERROR(IF(FIND("1",$D46),H$1,""),"") | I46: =IFERROR(IF(FIND("2",$D46),I$1,""),"") | J46: =IFERROR(IF(FIND("3",$D46),J$1,""),"") -> Wed | K46: =IFERROR(IF(FIND("4",$D46),K$1,""),"") | L46: =IFERROR(IF(FIND("5",$D46),L$1,""),"") | M46: {=_xludf.CONCAT("every ",_xludf.TEXTJOIN(", ", TRUE, IF(H46:L46<>"", H46:L46, "")))} -> #NAME?
A47: SB | B47: Chapel | C47: Empty Trash Large | D47: 5 | E47: Ryan | F47: {=INDEX(Tasks!$B:$B, MATCH(C47, Tasks!$A:$A, 0))} -> Empty trash being careful of leaking bags. | G47: {=_xludf.LET( _xlpm.task,$C47, _xlpm.r, _xludf.XMATCH(_xlpm.task, Tasks!$A:$A, 0), _xlpm.equip, Tasks!$C$1:$Y$1, _xlpm.flags, INDEX(Tasks!$C:$Y, _xlpm.r, 0), _xlpm.needed, _xlws.FILTER(_xlpm.equip, LOWER(_xlpm.flags)="x"), IFERROR("Equipment: " & _xludf.TEXTJOIN(", ", TRUE, _xlpm.needed), "Equipment: ") )} -> #NAME? | H47: =IFERROR(IF(FIND("1",$D47),H$1,""),"") | I47: =IFERROR(IF(FIND("2",$D47),I$1,""),"") | J47: =IFERROR(IF(FIND("3",$D47),J$1,""),"") | K47: =IFERROR(IF(FIND("4",$D47),K$1,""),"") | L47: =IFERROR(IF(FIND("5",$D47),L$1,""),"") -> Fri | M47: {=_xludf.CONCAT("every ",_xludf.TEXTJOIN(", ", TRUE, IF(H47:L47<>"", H47:L47, "")))} -> #NAME?
A48: SB | B48: Chapel | C48: Vacuum Light Traffic | D48: 5 | E48: Ryan | F48: {=INDEX(Tasks!$B:$B, MATCH(C48, Tasks!$A:$A, 0))} -> Use Backpack Vacuum. | G48: {=_xludf.LET( _xlpm.task,$C48, _xlpm.r, _xludf.XMATCH(_xlpm.task, Tasks!$A:$A, 0), _xlpm.equip, Tasks!$C$1:$Y$1, _xlpm.flags, INDEX(Tasks!$C:$Y, _xlpm.r, 0), _xlpm.needed, _xlws.FILTER(_xlpm.equip, LOWER(_xlpm.flags)="x"), IFERROR("Equipment: " & _xludf.TEXTJOIN(", ", TRUE, _xlpm.needed), "Equipment: ") )} -> #NAME? | H48: =IFERROR(IF(FIND("1",$D48),H$1,""),"") | I48: =IFERROR(IF(FIND("2",$D48),I$1,""),"") | J48: =IFERROR(IF(FIND("3",$D48),J$1,""),"") | K48: =IFERROR(IF(FIND("4",$D48),K$1,""),"") | L48: =IFERROR(IF(FIND("5",$D48),L$1,""),"") -> Fri | M48: {=_xludf.CONCAT("every ",_xludf.TEXTJOIN(", ", TRUE, IF(H48:L48<>"", H48:L48, "")))} -> #NAME?
A49: NB | B49: Children's Lobby | C49: Empty Trash Small | D49: 3 | E49: Ryan | F49: {=INDEX(Tasks!$B:$B, MATCH(C49, Tasks!$A:$A, 0))} -> Empty trash being careful of leaking bags. | G49: {=_xludf.LET( _xlpm.task,$C49, _xlpm.r, _xludf.XMATCH(_xlpm.task, Tasks!$A:$A, 0), _xlpm.equip, Tasks!$C$1:$Y$1, _xlpm.flags, INDEX(Tasks!$C:$Y, _xlpm.r, 0), _xlpm.needed, _xlws.FILTER(_xlpm.equip, LOWER(_xlpm.flags)="x"), IFERROR("Equipment: " & _xludf.TEXTJOIN(", ", TRUE, _xlpm.needed), "Equipment: ") )} -> #NAME? | H49: =IFERROR(IF(FIND("1",$D49),H$1,""),"") | I49: =IFERROR(IF(FIND("2",$D49),I$1,""),"") | J49: =IFERROR(IF(FIND("3",$D49),J$1,""),"") -> Wed | K49: =IFERROR(IF(FIND("4",$D49),K$1,""),"") | L49: =IFERROR(IF(FIND("5",$D49),L$1,""),"") | M49: {=_xludf.CONCAT("every ",_xludf.TEXTJOIN(", ", TRUE, IF(H49:L49<>"", H49:L49, "")))} -> #NAME?
A50: NB | B50: Children's Lobby | C50: Vacuum Light Traffic | D50: 5 | E50: Josh | F50: {=INDEX(Tasks!$B:$B, MATCH(C50, Tasks!$A:$A, 0))} -> Use Backpack Vacuum. | G50: {=_xludf.LET( _xlpm.task,$C50, _xlpm.r, _xludf.XMATCH(_xlpm.task, Tasks!$A:$A, 0), _xlpm.equip, Tasks!$C$1:$Y$1, _xlpm.flags, INDEX(Tasks!$C:$Y, _xlpm.r, 0), _xlpm.needed, _xlws.FILTER(_xlpm.equip, LOWER(_xlpm.flags)="x"), IFERROR("Equipment: " & _xludf.TEXTJOIN(", ", TRUE, _xlpm.needed), "Equipment: ") )} -> #NAME? | H50: =IFERROR(IF(FIND("1",$D50),H$1,""),"") | I50: =IFERROR(IF(FIND("2",$D50),I$1,""),"") | J50: =IFERROR(IF(FIND("3",$D50),J$1,""),"") | K50: =IFERROR(IF(FIND("4",$D50),K$1,""),"") | L50: =IFERROR(IF(FIND("5",$D50),L$1,""),"") -> Fri | M50: {=_xludf.CONCAT("every ",_xludf.TEXTJOIN(", ", TRUE, IF(H50:L50<>"", H50:L50, "")))} -> #NAME?
A51: NB | B51: Children's Lobby | C51: Vacuum Stairs | D51: 5 | E51: Josh | F51: {=INDEX(Tasks!$B:$B, MATCH(C51, Tasks!$A:$A, 0))} -> Use handheld Vacuum from janitorial closet. | G51: {=_xludf.LET( _xlpm.task,$C51, _xlpm.r, _xludf.XMATCH(_xlpm.task, Tasks!$A:$A, 0), _xlpm.equip, Tasks!$C$1:$Y$1, _xlpm.flags, INDEX(Tasks!$C:$Y, _xlpm.r, 0), _xlpm.needed, _xlws.FILTER(_xlpm.equip, LOWER(_xlpm.flags)="x"), IFERROR("Equipment: " & _xludf.TEXTJOIN(", ", TRUE, _xlpm.needed), "Equipment: ") )} -> #NAME? | H51: =IFERROR(IF(FIND("1",$D51),H$1,""),"") | I51: =IFERROR(IF(FIND("2",$D51),I$1,""),"") | J51: =IFERROR(IF(FIND("3",$D51),J$1,""),"") | K51: =IFERROR(IF(FIND("4",$D51),K$1,""),"") | L51: =IFERROR(IF(FIND("5",$D51),L$1,""),"") -> Fri | M51: {=_xludf.CONCAT("every ",_xludf.TEXTJOIN(", ", TRUE, IF(H51:L51<>"", H51:L51, "")))} -> #NAME?
A52: NB | B52: Children's Lobby | C52: Wipe down Stair Rails | D52: 3 | E52: Ryan | F52: {=INDEX(Tasks!$B:$B, MATCH(C52, Tasks!$A:$A, 0))} -> Spray 2in1 on a Paper Towel and wipe down surfaces. | G52: {=_xludf.LET( _xlpm.task,$C52, _xlpm.r, _xludf.XMATCH(_xlpm.task, Tasks!$A:$A, 0), _xlpm.equip, Tasks!$C$1:$Y$1, _xlpm.flags, INDEX(Tasks!$C:$Y, _xlpm.r, 0), _xlpm.needed, _xlws.FILTER(_xlpm.equip, LOWER(_xlpm.flags)="x"), IFERROR("Equipment: " & _xludf.TEXTJOIN(", ", TRUE, _xlpm.needed), "Equipment: ") )} -> #NAME? | H52: =IFERROR(IF(FIND("1",$D52),H$1,""),"") | I52: =IFERROR(IF(FIND("2",$D52),I$1,""),"") | J52: =IFERROR(IF(FIND("3",$D52),J$1,""),"") -> Wed | K52: =IFERROR(IF(FIND("4",$D52),K$1,""),"") | L52: =IFERROR(IF(FIND("5",$D52),L$1,""),"") | M52: {=_xludf.CONCAT("every ",_xludf.TEXTJOIN(", ", TRUE, IF(H52:L52<>"", H52:L52, "")))} -> #NAME?
A53: NB | B53: Children's Lobby | C53: Wipe down Tables | D53: 3 | E53: Ryan | F53: {=INDEX(Tasks!$B:$B, MATCH(C53, Tasks!$A:$A, 0))} -> Spray with 2in1, wipe with Paper Towel. | G53: {=_xludf.LET( _xlpm.task,$C53, _xlpm.r, _xludf.XMATCH(_xlpm.task, Tasks!$A:$A, 0), _xlpm.equip, Tasks!$C$1:$Y$1, _xlpm.flags, INDEX(Tasks!$C:$Y, _xlpm.r, 0), _xlpm.needed, _xlws.FILTER(_xlpm.equip, LOWER(_xlpm.flags)="x"), IFERROR("Equipment: " & _xludf.TEXTJOIN(", ", TRUE, _xlpm.needed), "Equipment: ") )} -> #NAME? | H53: =IFERROR(IF(FIND("1",$D53),H$1,""),"") | I53: =IFERROR(IF(FIND("2",$D53),I$1,""),"") | J53: =IFERROR(IF(FIND("3",$D53),J$1,""),"") -> Wed | K53: =IFERROR(IF(FIND("4",$D53),K$1,""),"") | L53: =IFERROR(IF(FIND("5",$D53),L$1,""),"") | M53: {=_xludf.CONCAT("every ",_xludf.TEXTJOIN(", ", TRUE, IF(H53:L53<>"", H53:L53, "")))} -> #NAME?
A54: NB | B54: Coffee | C54: Empty Trash Large | D54: 1 | E54: Ryan | F54: {=INDEX(Tasks!$B:$B, MATCH(C54, Tasks!$A:$A, 0))} -> Empty trash being careful of leaking bags. | G54: {=_xludf.LET( _xlpm.task,$C54, _xlpm.r, _xludf.XMATCH(_xlpm.task, Tasks!$A:$A, 0), _xlpm.equip, Tasks!$C$1:$Y$1, _xlpm.flags, INDEX(Tasks!$C:$Y, _xlpm.r, 0), _xlpm.needed, _xlws.FILTER(_xlpm.equip, LOWER(_xlpm.flags)="x"), IFERROR("Equipment: " & _xludf.TEXTJOIN(", ", TRUE, _xlpm.needed), "Equipment: ") )} -> #NAME? | H54: =IFERROR(IF(FIND("1",$D54),H$1,""),"") -> Mon | I54: =IFERROR(IF(FIND("2",$D54),I$1,""),"") | J54: =IFERROR(IF(FIND("3",$D54),J$1,""),"") | K54: =IFERROR(IF(FIND("4",$D54),K$1,""),"") | L54: =IFERROR(IF(FIND("5",$D54),L$1,""),"") | M54: {=_xludf.CONCAT("every ",_xludf.TEXTJOIN(", ", TRUE, IF(H54:L54<>"", H54:L54, "")))} -> #NAME?
A55: NB | B55: Coffee | C55: Mop | D55: 2 | E55: Ryan | F55: {=INDEX(Tasks!$B:$B, MATCH(C55, Tasks!$A:$A, 0))} -> Mix 6oz floor cleaner and 3gal hot water in mop bucket. | G55: {=_xludf.LET( _xlpm.task,$C55, _xlpm.r, _xludf.XMATCH(_xlpm.task, Tasks!$A:$A, 0), _xlpm.equip, Tasks!$C$1:$Y$1, _xlpm.flags, INDEX(Tasks!$C:$Y, _xlpm.r, 0), _xlpm.needed, _xlws.FILTER(_xlpm.equip, LOWER(_xlpm.flags)="x"), IFERROR("Equipment: " & _xludf.TEXTJOIN(", ", TRUE, _xlpm.needed), "Equipment: ") )} -> #NAME? | H55: =IFERROR(IF(FIND("1",$D55),H$1,""),"") | I55: =IFERROR(IF(FIND("2",$D55),I$1,""),"") -> Tue | J55: =IFERROR(IF(FIND("3",$D55),J$1,""),"") | K55: =IFERROR(IF(FIND("4",$D55),K$1,""),"") | L55: =IFERROR(IF(FIND("5",$D55),L$1,""),"") | M55: {=_xludf.CONCAT("every ",_xludf.TEXTJOIN(", ", TRUE, IF(H55:L55<>"", H55:L55, "")))} -> #NAME?
A56: NB | B56: Coffee | C56: Sweep | D56: 2 | E56: Ryan | F56: {=INDEX(Tasks!$B:$B, MATCH(C56, Tasks!$A:$A, 0))} -> Sweep Floors with broom. | G56: {=_xludf.LET( _xlpm.task,$C56, _xlpm.r, _xludf.XMATCH(_xlpm.task, Tasks!$A:$A, 0), _xlpm.equip, Tasks!$C$1:$Y$1, _xlpm.flags, INDEX(Tasks!$C:$Y, _xlpm.r, 0), _xlpm.needed, _xlws.FILTER(_xlpm.equip, LOWER(_xlpm.flags)="x"), IFERROR("Equipment: " & _xludf.TEXTJOIN(", ", TRUE, _xlpm.needed), "Equipment: ") )} -> #NAME? | H56: =IFERROR(IF(FIND("1",$D56),H$1,""),"") | I56: =IFERROR(IF(FIND("2",$D56),I$1,""),"") -> Tue | J56: =IFERROR(IF(FIND("3",$D56),J$1,""),"") | K56: =IFERROR(IF(FIND("4",$D56),K$1,""),"") | L56: =IFERROR(IF(FIND("5",$D56),L$1,""),"") | M56: {=_xludf.CONCAT("every ",_xludf.TEXTJOIN(", ", TRUE, IF(H56:L56<>"", H56:L56, "")))} -> #NAME?
A57: NB | B57: Corridor A | C57: Clean Carpets | D57: 1 | E57: Josh | F57: {=INDEX(Tasks!$B:$B, MATCH(C57, Tasks!$A:$A, 0))} -> Use Carpet Machine to clean Coffee Stains. | G57: {=_xludf.LET( _xlpm.task,$C57, _xlpm.r, _xludf.XMATCH(_xlpm.task, Tasks!$A:$A, 0), _xlpm.equip, Tasks!$C$1:$Y$1, _xlpm.flags, INDEX(Tasks!$C:$Y, _xlpm.r, 0), _xlpm.needed, _xlws.FILTER(_xlpm.equip, LOWER(_xlpm.flags)="x"), IFERROR("Equipment: " & _xludf.TEXTJOIN(", ", TRUE, _xlpm.needed), "Equipment: ") )} -> #NAME? | H57: =IFERROR(IF(FIND("1",$D57),H$1,""),"") -> Mon | I57: =IFERROR(IF(FIND("2",$D57),I$1,""),"") | J57: =IFERROR(IF(FIND("3",$D57),J$1,""),"") | K57: =IFERROR(IF(FIND("4",$D57),K$1,""),"") | L57: =IFERROR(IF(FIND("5",$D57),L$1,""),"") | M57: {=_xludf.CONCAT("every ",_xludf.TEXTJOIN(", ", TRUE, IF(H57:L57<>"", H57:L57, "")))} -> #NAME?
A58: NB | B58: Corridor A | C58: Disinfect Water Fountain | D58: 4 | E58: Ryan | F58: {=INDEX(Tasks!$B:$B, MATCH(C58, Tasks!$A:$A, 0))} -> Spray 2in1 on fountain and wipe off with Paper Towels. | G58: {=_xludf.LET( _xlpm.task,$C58, _xlpm.r, _xludf.XMATCH(_xlpm.task, Tasks!$A:$A, 0), _xlpm.equip, Tasks!$C$1:$Y$1, _xlpm.flags, INDEX(Tasks!$C:$Y, _xlpm.r, 0), _xlpm.needed, _xlws.FILTER(_xlpm.equip, LOWER(_xlpm.flags)="x"), IFERROR("Equipment: " & _xludf.TEXTJOIN(", ", TRUE, _xlpm.needed), "Equipment: ") )} -> #NAME? | H58: =IFERROR(IF(FIND("1",$D58),H$1,""),"") | I58: =IFERROR(IF(FIND("2",$D58),I$1,""),"") | J58: =IFERROR(IF(FIND("3",$D58),J$1,""),"") | K58: =IFERROR(IF(FIND("4",$D58),K$1,""),"") -> Thu | L58: =IFERROR(IF(FIND("5",$D58),L$1,""),"") | M58: {=_xludf.CONCAT("every ",_xludf.TEXTJOIN(", ", TRUE, IF(H58:L58<>"", H58:L58, "")))} -> #NAME?
... A128: NB | B128: Nursery | C128: Empty Diaper Genie | D128: 1 | E128: Ryan | F128: {=INDEX(Tasks!$B:$B, MATCH(C128, Tasks!$A:$A, 0))} -> Empty from below. | G128: {=_xludf.LET( _xlpm.task,$C128, _xlpm.r, _xludf.XMATCH(_xlpm.task, Tasks!$A:$A, 0), _xlpm.equip, Tasks!$C$1:$Y$1, _xlpm.flags, INDEX(Tasks!$C:$Y, _xlpm.r, 0), _xlpm.needed, _xlws.FILTER(_xlpm.equip, LOWER(_xlpm.flags)="x"), IFERROR("Equipment: " & _xludf.TEXTJOIN(", ", TRUE, _xlpm.needed), "Equipment: ") )} -> #NAME? | H128: =IFERROR(IF(FIND("1",$D128),H$1,""),"") -> Mon | I128: =IFERROR(IF(FIND("2",$D128),I$1,""),"") | J128: =IFERROR(IF(FIND("3",$D128),J$1,""),"") | K128: =IFERROR(IF(FIND("4",$D128),K$1,""),"") | L128: =IFERROR(IF(FIND("5",$D128),L$1,""),"") | M128: {=_xludf.CONCAT("every ",_xludf.TEXTJOIN(", ", TRUE, IF(H128:L128<>"", H128:L128, "")))} -> #NAME?
A129: NB | B129: Nursery | C129: Empty Trash Small | D129: 3 | E129: Ryan | F129: {=INDEX(Tasks!$B:$B, MATCH(C129, Tasks!$A:$A, 0))} -> Empty trash being careful of leaking bags. | G129: {=_xludf.LET( _xlpm.task,$C129, _xlpm.r, _xludf.XMATCH(_xlpm.task, Tasks!$A:$A, 0), _xlpm.equip, Tasks!$C$1:$Y$1, _xlpm.flags, INDEX(Tasks!$C:$Y, _xlpm.r, 0), _xlpm.needed, _xlws.FILTER(_xlpm.equip, LOWER(_xlpm.flags)="x"), IFERROR("Equipment: " & _xludf.TEXTJOIN(", ", TRUE, _xlpm.needed), "Equipment: ") )} -> #NAME? | H129: Mon | I129: =IFERROR(IF(FIND("2",$D129),I$1,""),"") | J129: =IFERROR(IF(FIND("3",$D129),J$1,""),"") -> Wed | K129: =IFERROR(IF(FIND("4",$D129),K$1,""),"") | L129: =IFERROR(IF(FIND("5",$D129),L$1,""),"") | M129: {=_xludf.CONCAT("every ",_xludf.TEXTJOIN(", ", TRUE, IF(H129:L129<>"", H129:L129, "")))} -> #NAME?
A130: NB | B130: Nursery | C130: Wipe down Stair Rails | D130: 3 | E130: Ryan | F130: {=INDEX(Tasks!$B:$B, MATCH(C130, Tasks!$A:$A, 0))} -> Spray 2in1 on a Paper Towel and wipe down surfaces. | G130: {=_xludf.LET( _xlpm.task,$C130, _xlpm.r, _xludf.XMATCH(_xlpm.task, Tasks!$A:$A, 0), _xlpm.equip, Tasks!$C$1:$Y$1, _xlpm.flags, INDEX(Tasks!$C:$Y, _xlpm.r, 0), _xlpm.needed, _xlws.FILTER(_xlpm.equip, LOWER(_xlpm.flags)="x"), IFERROR("Equipment: " & _xludf.TEXTJOIN(", ", TRUE, _xlpm.needed), "Equipment: ") )} -> #NAME? | I130: =IFERROR(IF(FIND("2",$D130),I$1,""),"") | J130: =IFERROR(IF(FIND("3",$D130),J$1,""),"") -> Wed | K130: =IFERROR(IF(FIND("4",$D130),K$1,""),"") | L130: =IFERROR(IF(FIND("5",$D130),L$1,""),"") | M130: {=_xludf.CONCAT("every ",_xludf.TEXTJOIN(", ", TRUE, IF(H130:L130<>"", H130:L130, "")))} -> #NAME?
A131: NB | B131: Nursery | C131: Vacuum Light Traffic | D131: 3 | E131: Ryan | F131: {=INDEX(Tasks!$B:$B, MATCH(C131, Tasks!$A:$A, 0))} -> Use Backpack Vacuum. | G131: {=_xludf.LET( _xlpm.task,$C131, _xlpm.r, _xludf.XMATCH(_xlpm.task, Tasks!$A:$A, 0), _xlpm.equip, Tasks!$C$1:$Y$1, _xlpm.flags, INDEX(Tasks!$C:$Y, _xlpm.r, 0), _xlpm.needed, _xlws.FILTER(_xlpm.equip, LOWER(_xlpm.flags)="x"), IFERROR("Equipment: " & _xludf.TEXTJOIN(", ", TRUE, _xlpm.needed), "Equipment: ") )} -> #NAME? | H131: Mon | I131: =IFERROR(IF(FIND("2",$D131),I$1,""),"") | J131: =IFERROR(IF(FIND("3",$D131),J$1,""),"") -> Wed | K131: =IFERROR(IF(FIND("4",$D131),K$1,""),"") | L131: =IFERROR(IF(FIND("5",$D131),L$1,""),"") | M131: {=_xludf.CONCAT("every ",_xludf.TEXTJOIN(", ", TRUE, IF(H131:L131<>"", H131:L131, "")))} -> #NAME?
A132: NB | B132: Nursery | C132: Wipe down Counters | D132: 3 | E132: Ryan | F132: {=INDEX(Tasks!$B:$B, MATCH(C132, Tasks!$A:$A, 0))} -> Spray with 2in1, wipe with Paper Towel. | G132: {=_xludf.LET( _xlpm.task,$C132, _xlpm.r, _xludf.XMATCH(_xlpm.task, Tasks!$A:$A, 0), _xlpm.equip, Tasks!$C$1:$Y$1, _xlpm.flags, INDEX(Tasks!$C:$Y, _xlpm.r, 0), _xlpm.needed, _xlws.FILTER(_xlpm.equip, LOWER(_xlpm.flags)="x"), IFERROR("Equipment: " & _xludf.TEXTJOIN(", ", TRUE, _xlpm.needed), "Equipment: ") )} -> #NAME? | H132: Mon | I132: =IFERROR(IF(FIND("2",$D132),I$1,""),"") | J132: =IFERROR(IF(FIND("3",$D132),J$1,""),"") -> Wed | K132: =IFERROR(IF(FIND("4",$D132),K$1,""),"") | L132: =IFERROR(IF(FIND("5",$D132),L$1,""),"") | M132: {=_xludf.CONCAT("every ",_xludf.TEXTJOIN(", ", TRUE, IF(H132:L132<>"", H132:L132, "")))} -> #NAME?
A133: NB | B133: Office Downstairs | C133: Empty Trash Small | D133: 5 | E133: Josh | F133: {=INDEX(Tasks!$B:$B, MATCH(C133, Tasks!$A:$A, 0))} -> Empty trash being careful of leaking bags. | G133: {=_xludf.LET( _xlpm.task,$C133, _xlpm.r, _xludf.XMATCH(_xlpm.task, Tasks!$A:$A, 0), _xlpm.equip, Tasks!$C$1:$Y$1, _xlpm.flags, INDEX(Tasks!$C:$Y, _xlpm.r, 0), _xlpm.needed, _xlws.FILTER(_xlpm.equip, LOWER(_xlpm.flags)="x"), IFERROR("Equipment: " & _xludf.TEXTJOIN(", ", TRUE, _xlpm.needed), "Equipment: ") )} -> #NAME? | H133: =IFERROR(IF(FIND("1",$D133),H$1,""),"") | I133: =IFERROR(IF(FIND("2",$D133),I$1,""),"") | J133: =IFERROR(IF(FIND("3",$D133),J$1,""),"") | K133: =IFERROR(IF(FIND("4",$D133),K$1,""),"") | L133: =IFERROR(IF(FIND("5",$D133),L$1,""),"") -> Fri | M133: {=_xludf.CONCAT("every ",_xludf.TEXTJOIN(", ", TRUE, IF(H133:L133<>"", H133:L133, "")))} -> #NAME?
A134: NB | B134: Office Downstairs | C134: Vacuum Light Traffic | D134: 5 | E134: Josh | F134: {=INDEX(Tasks!$B:$B, MATCH(C134, Tasks!$A:$A, 0))} -> Use Backpack Vacuum. | G134: {=_xludf.LET( _xlpm.task,$C134, _xlpm.r, _xludf.XMATCH(_xlpm.task, Tasks!$A:$A, 0), _xlpm.equip, Tasks!$C$1:$Y$1, _xlpm.flags, INDEX(Tasks!$C:$Y, _xlpm.r, 0), _xlpm.needed, _xlws.FILTER(_xlpm.equip, LOWER(_xlpm.flags)="x"), IFERROR("Equipment: " & _xludf.TEXTJOIN(", ", TRUE, _xlpm.needed), "Equipment: ") )} -> #NAME? | H134: =IFERROR(IF(FIND("1",$D134),H$1,""),"") | I134: =IFERROR(IF(FIND("2",$D134),I$1,""),"") | J134: =IFERROR(IF(FIND("3",$D134),J$1,""),"") | K134: =IFERROR(IF(FIND("4",$D134),K$1,""),"") | L134: =IFERROR(IF(FIND("5",$D134),L$1,""),"") -> Fri | M134: {=_xludf.CONCAT("every ",_xludf.TEXTJOIN(", ", TRUE, IF(H134:L134<>"", H134:L134, "")))} -> #NAME?
A135: NB | B135: Office Upstairs | C135: Empty Trash Small | D135: 5 | E135: Josh | F135: {=INDEX(Tasks!$B:$B, MATCH(C135, Tasks!$A:$A, 0))} -> Empty trash being careful of leaking bags. | G135: {=_xludf.LET( _xlpm.task,$C135, _xlpm.r, _xludf.XMATCH(_xlpm.task, Tasks!$A:$A, 0), _xlpm.equip, Tasks!$C$1:$Y$1, _xlpm.flags, INDEX(Tasks!$C:$Y, _xlpm.r, 0), _xlpm.needed, _xlws.FILTER(_xlpm.equip, LOWER(_xlpm.flags)="x"), IFERROR("Equipment: " & _xludf.TEXTJOIN(", ", TRUE, _xlpm.needed), "Equipment: ") )} -> #NAME? | H135: =IFERROR(IF(FIND("1",$D135),H$1,""),"") | I135: =IFERROR(IF(FIND("2",$D135),I$1,""),"") | J135: =IFERROR(IF(FIND("3",$D135),J$1,""),"") | K135: =IFERROR(IF(FIND("4",$D135),K$1,""),"") | L135: =IFERROR(IF(FIND("5",$D135),L$1,""),"") -> Fri | M135: {=_xludf.CONCAT("every ",_xludf.TEXTJOIN(", ", TRUE, IF(H135:L135<>"", H135:L135, "")))} -> #NAME?
A136: NB | B136: Office Upstairs | C136: Vacuum Light Traffic | D136: 5 | E136: Josh | F136: {=INDEX(Tasks!$B:$B, MATCH(C136, Tasks!$A:$A, 0))} -> Use Backpack Vacuum. | G136: {=_xludf.LET( _xlpm.task,$C136, _xlpm.r, _xludf.XMATCH(_xlpm.task, Tasks!$A:$A, 0), _xlpm.equip, Tasks!$C$1:$Y$1, _xlpm.flags, INDEX(Tasks!$C:$Y, _xlpm.r, 0), _xlpm.needed, _xlws.FILTER(_xlpm.equip, LOWER(_xlpm.flags)="x"), IFERROR("Equipment: " & _xludf.TEXTJOIN(", ", TRUE, _xlpm.needed), "Equipment: ") )} -> #NAME? | H136: =IFERROR(IF(FIND("1",$D136),H$1,""),"") | I136: =IFERROR(IF(FIND("2",$D136),I$1,""),"") | J136: =IFERROR(IF(FIND("3",$D136),J$1,""),"") | K136: =IFERROR(IF(FIND("4",$D136),K$1,""),"") | L136: =IFERROR(IF(FIND("5",$D136),L$1,""),"") -> Fri | M136: {=_xludf.CONCAT("every ",_xludf.TEXTJOIN(", ", TRUE, IF(H136:L136<>"", H136:L136, "")))} -> #NAME?
A137: NB | B137: Prayer Rooms | C137: Empty Trash Small | D137: 2 | E137: Ryan | F137: {=INDEX(Tasks!$B:$B, MATCH(C137, Tasks!$A:$A, 0))} -> Empty trash being careful of leaking bags. | G137: {=_xludf.LET( _xlpm.task,$C137, _xlpm.r, _xludf.XMATCH(_xlpm.task, Tasks!$A:$A, 0), _xlpm.equip, Tasks!$C$1:$Y$1, _xlpm.flags, INDEX(Tasks!$C:$Y, _xlpm.r, 0), _xlpm.needed, _xlws.FILTER(_xlpm.equip, LOWER(_xlpm.flags)="x"), IFERROR("Equipment: " & _xludf.TEXTJOIN(", ", TRUE, _xlpm.needed), "Equipment: ") )} -> #NAME? | H137: =IFERROR(IF(FIND("1",$D137),H$1,""),"") | I137: =IFERROR(IF(FIND("2",$D137),I$1,""),"") -> Tue | J137: =IFERROR(IF(FIND("3",$D137),J$1,""),"") | K137: =IFERROR(IF(FIND("4",$D137),K$1,""),"") | L137: =IFERROR(IF(FIND("5",$D137),L$1,""),"") | M137: {=_xludf.CONCAT("every ",_xludf.TEXTJOIN(", ", TRUE, IF(H137:L137<>"", H137:L137, "")))} -> #NAME?
A138: NB | B138: Prayer Rooms | C138: Vacuum Light Traffic | D138: 2 | E138: Ryan | F138: {=INDEX(Tasks!$B:$B, MATCH(C138, Tasks!$A:$A, 0))} -> Use Backpack Vacuum. | G138: {=_xludf.LET( _xlpm.task,$C138, _xlpm.r, _xludf.XMATCH(_xlpm.task, Tasks!$A:$A, 0), _xlpm.equip, Tasks!$C$1:$Y$1, _xlpm.flags, INDEX(Tasks!$C:$Y, _xlpm.r, 0), _xlpm.needed, _xlws.FILTER(_xlpm.equip, LOWER(_xlpm.flags)="x"), IFERROR("Equipment: " & _xludf.TEXTJOIN(", ", TRUE, _xlpm.needed), "Equipment: ") )} -> #NAME? | H138: =IFERROR(IF(FIND("1",$D138),H$1,""),"") | I138: =IFERROR(IF(FIND("2",$D138),I$1,""),"") -> Tue | J138: =IFERROR(IF(FIND("3",$D138),J$1,""),"") | K138: =IFERROR(IF(FIND("4",$D138),K$1,""),"") | L138: =IFERROR(IF(FIND("5",$D138),L$1,""),"") | M138: {=_xludf.CONCAT("every ",_xludf.TEXTJOIN(", ", TRUE, IF(H138:L138<>"", H138:L138, "")))} -> #NAME?
A139: NB | B139: Prayer Rooms | C139: Wipe down Tables | D139: 2 | E139: Ryan | F139: {=INDEX(Tasks!$B:$B, MATCH(C139, Tasks!$A:$A, 0))} -> Spray with 2in1, wipe with Paper Towel. | G139: {=_xludf.LET( _xlpm.task,$C139, _xlpm.r, _xludf.XMATCH(_xlpm.task, Tasks!$A:$A, 0), _xlpm.equip, Tasks!$C$1:$Y$1, _xlpm.flags, INDEX(Tasks!$C:$Y, _xlpm.r, 0), _xlpm.needed, _xlws.FILTER(_xlpm.equip, LOWER(_xlpm.flags)="x"), IFERROR("Equipment: " & _xludf.TEXTJOIN(", ", TRUE, _xlpm.needed), "Equipment: ") )} -> #NAME? | H139: =IFERROR(IF(FIND("1",$D139),H$1,""),"") | I139: =IFERROR(IF(FIND("2",$D139),I$1,""),"") -> Tue | J139: =IFERROR(IF(FIND("3",$D139),J$1,""),"") | K139: =IFERROR(IF(FIND("4",$D139),K$1,""),"") | L139: =IFERROR(IF(FIND("5",$D139),L$1,""),"") | M139: {=_xludf.CONCAT("every ",_xludf.TEXTJOIN(", ", TRUE, IF(H139:L139<>"", H139:L139, "")))} -> #NAME?
A140: NB | B140: Preschool East | C140: Empty Trash Small | D140: 3 | E140: Ryan | F140: {=INDEX(Tasks!$B:$B, MATCH(C140, Tasks!$A:$A, 0))} -> Empty trash being careful of leaking bags. | G140: {=_xludf.LET( _xlpm.task,$C140, _xlpm.r, _xludf.XMATCH(_xlpm.task, Tasks!$A:$A, 0), _xlpm.equip, Tasks!$C$1:$Y$1, _xlpm.flags, INDEX(Tasks!$C:$Y, _xlpm.r, 0), _xlpm.needed, _xlws.FILTER(_xlpm.equip, LOWER(_xlpm.flags)="x"), IFERROR("Equipment: " & _xludf.TEXTJOIN(", ", TRUE, _xlpm.needed), "Equipment: ") )} -> #NAME? | H140: =IFERROR(IF(FIND("1",$D140),H$1,""),"") | I140: =IFERROR(IF(FIND("2",$D140),I$1,""),"") | J140: =IFERROR(IF(FIND("3",$D140),J$1,""),"") -> Wed | K140: =IFERROR(IF(FIND("4",$D140),K$1,""),"") | L140: =IFERROR(IF(FIND("5",$D140),L$1,""),"") | M140: {=_xludf.CONCAT("every ",_xludf.TEXTJOIN(", ", TRUE, IF(H140:L140<>"", H140:L140, "")))} -> #NAME?
A141: NB | B141: Preschool East | C141: Vacuum Light Traffic | D141: 3 | E141: Ryan | F141: {=INDEX(Tasks!$B:$B, MATCH(C141, Tasks!$A:$A, 0))} -> Use Backpack Vacuum. | G141: {=_xludf.LET( _xlpm.task,$C141, _xlpm.r, _xludf.XMATCH(_xlpm.task, Tasks!$A:$A, 0), _xlpm.equip, Tasks!$C$1:$Y$1, _xlpm.flags, INDEX(Tasks!$C:$Y, _xlpm.r, 0), _xlpm.needed, _xlws.FILTER(_xlpm.equip, LOWER(_xlpm.flags)="x"), IFERROR("Equipment: " & _xludf.TEXTJOIN(", ", TRUE, _xlpm.needed), "Equipment: ") )} -> #NAME? | H141: =IFERROR(IF(FIND("1",$D141),H$1,""),"") | I141: =IFERROR(IF(FIND("2",$D141),I$1,""),"") | J141: =IFERROR(IF(FIND("3",$D141),J$1,""),"") -> Wed | K141: =IFERROR(IF(FIND("4",$D141),K$1,""),"") | L141: =IFERROR(IF(FIND("5",$D141),L$1,""),"") | M141: {=_xludf.CONCAT("every ",_xludf.TEXTJOIN(", ", TRUE, IF(H141:L141<>"", H141:L141, "")))} -> #NAME?
...

Sheet Rooms
A1: NB Gym
A2: NB Hallway_Downstairs
A3: NB Hallway_Upstairs
A4: NB Sanctuary
A5: NB Lobby
A6: NB Fireside_Room
A7: NB RR_Men_Downstairs_North
A8: NB RR_Men_Downstairs_South
A9: NB RR_Men_Upstairs
A10: NB RR_Nursery
A11: NB RR_Preschool
A12: NB RR_Women_Downstairs_North
... A66: SB Stage

Sheet Tasks
A1: Task | B1: Instructions | C1: 2in1 Cleaner | D1: Backpack Vacuum | E1: Barkeepers Friend | F1: Broom | G1: Carpet Cleaner | H1: Carpet Cleaner Solution | I1: Corded Vacuum | J1: Diaper Genie Refill | K1: Feminine Hygiene Bags | L1: Floor Cleaner | M1: Glass Cleaner | N1: Hand Soap Refill | O1: Hand Towel Refill | P1: Handheld Vacuum | Q1: Mop | R1: Paper Towel | S1: Shower Brush | T1: Sink Brush | U1: Toilet Bowl Cleaner | V1: Toilet Brush | W1: Toilet Paper Refill | X1: Trash bag Black | Y1: Trash bag Clear
A2: Breakdown Sunday | B2: Wipe down Tables with 2in1 and put away. Empty Coffee Trash. Roll up Rugs and store above Tables. Put Communion Elements in Refrigerator. | C2: x | R2: x | X2: x | AA2: =_xludf.CONCAT(B2,".") -> #NAME?
A3: Clean Carpets | B3: Use Carpet Machine to clean Coffee Stains. | G3: x | H3: x | AA3: =_xludf.CONCAT(B3,".") -> #NAME?
A4: Disinfect Changing Table | B4: Spray 2in1 on a Paper Towel and wipe down surfaces. | C4: x | R4: x | AA4: =_xludf.CONCAT(B4,".") -> #NAME?
A5: Disinfect Water Fountain | B5: Spray 2in1 on fountain and wipe off with Paper Towels. | C5: x | R5: x | AA5: =_xludf.CONCAT(B5,".") -> #NAME?
A6: Empty Diaper Genie | B6: Empty from below. | J6: x | AA6: =_xludf.CONCAT(B6,".") -> #NAME?
A7: Empty Trash Bathroom | B7: Empty trash Including stall bags. | K7: x | Y7: x | AA7: =_xludf.CONCAT(B7,".") -> #NAME?
A8: Empty Trash Large | B8: Empty trash being careful of leaking bags. | X8: x | AA8: =_xludf.CONCAT(B8,".") -> #NAME?
A9: Empty Trash Small | B9: Empty trash being careful of leaking bags. | Y9: x | AA9: =_xludf.CONCAT(B9,".") -> #NAME?
A10: Mop | B10: Mix 6oz floor cleaner and 3gal hot water in mop bucket. | L10: x | Q10: x | AA10: =_xludf.CONCAT(B10,".") -> #NAME?
A11: Pickup Trash | B11: Pickup communion cups and other trash on floor and seats, and in seat backs. | X11: x | AA11: =_xludf.CONCAT(B11,".") -> #NAME?
A12: Scrub Showers | B12: If used, spray shower with 2in1, scrub with shower brush, rinse with water. | C12: x | S12: x | AA12: =_xludf.CONCAT(B12,".") -> #NAME?
A13: Scrub Sinks | B13: Use Barkeepers Friend in bowl, Scrub with sink brush. Finish with 2in1 and Paper Towels. | E13: x | T13: x | AA13: =_xludf.CONCAT(B13,".") -> #NAME?
A14: Scrub Toilets | B14: Scrub Toilet Bowls with Toilet Bowl Cleaner and Toilet Brush. Spray entire Toilet with 2in1 and wipe with Paper Towels. | C14: x | R14: x | U14: x | V14: x | AA14: =_xludf.CONCAT(B14,".") -> #NAME?
A15: Scrub Urinals | B15: Scrub toilet bowls and urinals with brush and disinfect under seats. | C15: x | R15: x | U15: x | V15: x | AA15: =_xludf.CONCAT(B15,".") -> #NAME?
A16: Spot Clean Door Glass | B16: Clean handprints off glass doors. | M16: x | R16: x | AA16: =_xludf.CONCAT(B16,".") -> #NAME?
A17: Spot Clean Glass | B17: Clean visibly dirty spots. | M17: x | R17: x | AA17: =_xludf.CONCAT(B17,".") -> #NAME?
A18: Spot Clean Mirrors | B18: Clean visibly dirty spots. | M18: x | R18: x | AA18: =_xludf.CONCAT(B18,".") -> #NAME?
A19: Stock Bathroom Supplies | B19: Refill Paper Towels, hand soap, Toilet Paper. | N19: x | O19: x | W19: x | AA19: =_xludf.CONCAT(B19,".") -> #NAME?
A20: Stock Kitchen Supplies | B20: Refill Paper Towels and hand soap. | AA20: =_xludf.CONCAT(B20,".") -> #NAME?
A21: Straighten Chairs | B21: Arrange chairs in straight rows on floor marks. | AA21: =_xludf.CONCAT(B21,".") -> #NAME?
A22: Sweep | B22: Sweep Floors with broom. | F22: x | AA22: =_xludf.CONCAT(B22,".") -> #NAME?
A23: Sweep Stairs | B23: Sweep Stairs with broom. | F23: x | AA23: =_xludf.CONCAT(B23,".") -> #NAME?
A24: Vacuum Light Traffic | B24: Use Backpack Vacuum. | D24: x | AA24: =_xludf.CONCAT(B24,".") -> #NAME?
A25: Vacuum High Traffic | B25: Use corded Vacuum. | I25: x | AA25: =_xludf.CONCAT(B25,".") -> #NAME?
A26: Vacuum Rugs | B26: Use corded Vacuum. | I26: x | AA26: =_xludf.CONCAT(B26,".") -> #NAME?
A27: Vacuum Stairs | B27: Use handheld Vacuum from janitorial closet. | P27: x | AA27: =_xludf.CONCAT(B27,".") -> #NAME?
A28: Wash Towels | B28: Collect Towels from kitchens and janitorial closets in both buildings. Wash in Laundry Machine. Fold and return. | AA28: =_xludf.CONCAT(B28,".") -> #NAME?
A29: Wipe down Counters | B29: Spray with 2in1, wipe with Paper Towel. | C29: x | R29: x | AA29: =_xludf.CONCAT(B29,".") -> #NAME?
A30: Wipe down Sink | B30: Spray with 2in1, wipe with Paper Towel. | C30: x | R30: x | AA30: =_xludf.CONCAT(B30,".") -> #NAME?
A31: Wipe down Stair Rails | B31: Spray 2in1 on a Paper Towel and wipe down surfaces. | C31: x | R31: x | AA31: =_xludf.CONCAT(B31,".") -> #NAME?
A32: Wipe down Tables | B32: Spray with 2in1, wipe with Paper Towel. | C32: x | R32: x | AA32: =_xludf.CONCAT(B32,".") -> #NAME?
A33: Wipe down Toilets | B33: Spray Seat, Rim, and Handle with 2in1, wipe with Paper Towel. | C33: x | R33: x | AA33: =_xludf.CONCAT(B33,".") -> #NAME?
A34: Wipe down Urinals | B34: Spray Rim and Handle with 2in1, wipe with Paper Towel. | C34: x | R34: x | AA34: =_xludf.CONCAT(B34,".") -> #NAME?

Sheet Supplies
A1: Shower brush
A2: Sink Brush

Sheet Todoist Out
A1: TYPE | B1: CONTENT | C1: DESCRIPTION | D1: IS_COLLAPSED | E1: PRIORITY | F1: INDENT | G1: AUTHOR | H1: RESPONSIBLE | I1: DATE | J1: DATE_LANG | K1: TIMEZONE | L1: DURATION | M1: DURATION_UNIT | N1: DEADLINE | O1: DEADLINE_LANG
A2: meta | B2: view_style=list
A4: task | B4: =CONCATENATE(Weekly!C2," @",Weekly!A2,"_",Weekly!B2) -> Empty Trash Small @SB_100 | C4: =CONCATENATE(Weekly!F2," / ",Weekly!G2) -> #NAME? | E4: 1 | F4: 1 | G4: k.gunn (48758372) | H4: =LOOKUP(Weekly!E2,Workers!A:A,Workers!B:B) -> Ryan (57174722) | I4: =Weekly!M2 -> #NAME? | J4: en | K4: America/Los_Angeles
A5: task | B5: =CONCATENATE(Weekly!C3," @",Weekly!A3,"_",Weekly!B3) -> Vacuum Light Traffic @SB_100 | C5: =CONCATENATE(Weekly!F3," / ",Weekly!G3) -> #NAME? | E5: 1 | F5: 1 | G5: k.gunn (48758372) | H5: =LOOKUP(Weekly!E3,Workers!A:A,Workers!B:B) -> Ryan (57174722) | I5: =Weekly!M3 -> #NAME? | J5: en | K5: America/Los_Angeles
A6: task | B6: =CONCATENATE(Weekly!C4," @",Weekly!A4,"_",Weekly!B4) -> Wipe down Tables @SB_100 | C6: =CONCATENATE(Weekly!F4," / ",Weekly!G4) -> #NAME? | E6: 1 | F6: 1 | G6: k.gunn (48758372) | H6: =LOOKUP(Weekly!E4,Workers!A:A,Workers!B:B) -> Ryan (57174722) | I6: =Weekly!M4 -> #NAME? | J6: en | K6: America/Los_Angeles
A7: task | B7: =CONCATENATE(Weekly!C5," @",Weekly!A5,"_",Weekly!B5) -> Empty Trash Small @SB_101 | C7: =CONCATENATE(Weekly!F5," / ",Weekly!G5) -> #NAME? | E7: 1 | F7: 1 | G7: k.gunn (48758372) | H7: =LOOKUP(Weekly!E5,Workers!A:A,Workers!B:B) -> Ryan (57174722) | I7: =Weekly!M5 -> #NAME? | J7: en | K7: America/Los_Angeles
A8: task | B8: =CONCATENATE(Weekly!C6," @",Weekly!A6,"_",Weekly!B6) -> Vacuum Light Traffic @SB_101 | C8: =CONCATENATE(Weekly!F6," / ",Weekly!G6) -> #NAME? | E8: 1 | F8: 1 | G8: k.gunn (48758372) | H8: =LOOKUP(Weekly!E6,Workers!A:A,Workers!B:B) -> Ryan (57174722) | I8: =Weekly!M6 -> #NAME? | J8: en | K8: America/Los_Angeles
A9: task | B9: =CONCATENATE(Weekly!C7," @",Weekly!A7,"_",Weekly!B7) -> Wipe down Counters @SB_101 | C9: =CONCATENATE(Weekly!F7," / ",Weekly!G7) -> #NAME? | E9: 1 | F9: 1 | G9: k.gunn (48758372) | H9: =LOOKUP(Weekly!E7,Workers!A:A,Workers!B:B) -> Ryan (57174722) | I9: =Weekly!M7 -> #NAME? | J9: en | K9: America/Los_Angeles
A10: task | B10: =CONCATENATE(Weekly!C8," @",Weekly!A8,"_",Weekly!B8) -> Wipe down Tables @SB_101 | C10: =CONCATENATE(Weekly!F8," / ",Weekly!G8) -> #NAME? | E10: 1 | F10: 1 | G10: k.gunn (48758372) | H10: =LOOKUP(Weekly!E8,Workers!A:A,Workers!B:B) -> Ryan (57174722) | I10: =Weekly!M8 -> #NAME? | J10: en | K10: America/Los_Angeles
A11: task | B11: =CONCATENATE(Weekly!C9," @",Weekly!A9,"_",Weekly!B9) -> Empty Trash Small @SB_102 | C11: =CONCATENATE(Weekly!F9," / ",Weekly!G9) -> #NAME? | E11: 1 | F11: 1 | G11: k.gunn (48758372) | H11: =LOOKUP(Weekly!E9,Workers!A:A,Workers!B:B) -> Ryan (57174722) | I11: =Weekly!M9 -> #NAME? | J11: en | K11: America/Los_Angeles
A12: task | B12: =CONCATENATE(Weekly!C10," @",Weekly!A10,"_",Weekly!B10) -> Vacuum Light Traffic @SB_102 | C12: =CONCATENATE(Weekly!F10," / ",Weekly!G10) -> #NAME? | E12: 1 | F12: 1 | G12: k.gunn (48758372) | H12: =LOOKUP(Weekly!E10,Workers!A:A,Workers!B:B) -> Ryan (57174722) | I12: =Weekly!M10 -> #NAME? | J12: en | K12: America/Los_Angeles
A13: task | B13: =CONCATENATE(Weekly!C11," @",Weekly!A11,"_",Weekly!B11) -> Wipe down Counters @SB_102 | C13: =CONCATENATE(Weekly!F11," / ",Weekly!G11) -> #NAME? | E13: 1 | F13: 1 | G13: k.gunn (48758372) | H13: =LOOKUP(Weekly!E11,Workers!A:A,Workers!B:B) -> Ryan (57174722) | I13: =Weekly!M11 -> #NAME? | J13: en | K13: America/Los_Angeles
A14: task | B14: =CONCATENATE(Weekly!C12," @",Weekly!A12,"_",Weekly!B12) -> Wipe down Sink @SB_102 | C14: =CONCATENATE(Weekly!F12," / ",Weekly!G12) -> #NAME? | E14: 1 | F14: 1 | G14: k.gunn (48758372) | H14: =LOOKUP(Weekly!E12,Workers!A:A,Workers!B:B) -> Ryan (57174722) | I14: =Weekly!M12 -> #NAME? | J14: en | K14: America/Los_Angeles
A15: task | B15: =CONCATENATE(Weekly!C13," @",Weekly!A13,"_",Weekly!B13) -> Wipe down Tables @SB_102 | C15: =CONCATENATE(Weekly!F13," / ",Weekly!G13) -> #NAME? | E15: 1 | F15: 1 | G15: k.gunn (48758372) | H15: =LOOKUP(Weekly!E13,Workers!A:A,Workers!B:B) -> Ryan (57174722) | I15: =Weekly!M13 -> #NAME? | J15: en | K15: America/Los_Angeles
... A44: task | B44: =CONCATENATE(Weekly!C42," @",Weekly!A42,"_",Weekly!B42) -> Wipe down Tables @SB_204 | C44: =CONCATENATE(Weekly!F42," / ",Weekly!G42) -> #NAME? | E44: 1 | F44: 1 | G44: k.gunn (48758372) | H44: =LOOKUP(Weekly!E42,Workers!A:A,Workers!B:B) -> Ryan (57174722) | I44: =Weekly!M42 -> #NAME? | J44: en | K44: America/Los_Angeles
A45: task | B45: =CONCATENATE(Weekly!#REF!," @",Weekly!#REF!,"_",Weekly!#REF!) -> #REF! | C45: =CONCATENATE(Weekly!#REF!," / ",Weekly!#REF!) -> #REF! | E45: 1 | F45: 1 | G45: k.gunn (48758372) | H45: =LOOKUP(Weekly!#REF!,Workers!A:A,Workers!B:B) -> #REF! | I45: =Weekly!#REF! -> #REF! | J45: en | K45: America/Los_Angeles
A46: task | B46: =CONCATENATE(Weekly!#REF!," @",Weekly!#REF!,"_",Weekly!#REF!) -> #REF! | C46: =CONCATENATE(Weekly!#REF!," / ",Weekly!#REF!) -> #REF! | E46: 1 | F46: 1 | G46: k.gunn (48758372) | H46: =LOOKUP(Weekly!#REF!,Workers!A:A,Workers!B:B) -> #REF! | I46: =Weekly!#REF! -> #REF! | J46: en | K46: America/Los_Angeles
A47: task | B47: =CONCATENATE(Weekly!#REF!," @",Weekly!#REF!,"_",Weekly!#REF!) -> #REF! | C47: =CONCATENATE(Weekly!#REF!," / ",Weekly!#REF!) -> #REF! | E47: 1 | F47: 1 | G47: k.gunn (48758372) | H47: =LOOKUP(Weekly!#REF!,Workers!A:A,Workers!B:B) -> #REF! | I47: =Weekly!#REF! -> #REF! | J47: en | K47: America/Los_Angeles
A48: task | B48: =CONCATENATE(Weekly!C43," @",Weekly!A43,"_",Weekly!B43) -> Empty Trash Small @SB_205 | C48: =CONCATENATE(Weekly!F43," / ",Weekly!G43) -> #NAME? | E48: 1 | F48: 1 | G48: k.gunn (48758372) | H48: =LOOKUP(Weekly!E43,Workers!A:A,Workers!B:B) -> Ryan (57174722) | I48: =Weekly!M43 -> #NAME? | J48: en | K48: America/Los_Angeles
A49: task | B49: =CONCATENATE(Weekly!C44," @",Weekly!A44,"_",Weekly!B44) -> Vacuum Light Traffic @SB_205 | C49: =CONCATENATE(Weekly!F44," / ",Weekly!G44) -> #NAME? | E49: 1 | F49: 1 | G49: k.gunn (48758372) | H49: =LOOKUP(Weekly!E44,Workers!A:A,Workers!B:B) -> Ryan (57174722) | I49: =Weekly!M44 -> #NAME? | J49: en | K49: America/Los_Angeles
A50: task | B50: =CONCATENATE(Weekly!C45," @",Weekly!A45,"_",Weekly!B45) -> Wipe down Counters @SB_205 | C50: =CONCATENATE(Weekly!F45," / ",Weekly!G45) -> #NAME? | E50: 1 | F50: 1 | G50: k.gunn (48758372) | H50: =LOOKUP(Weekly!E45,Workers!A:A,Workers!B:B) -> Ryan (57174722) | I50: =Weekly!M45 -> #NAME? | J50: en | K50: America/Los_Angeles
A51: task | B51: =CONCATENATE(Weekly!C46," @",Weekly!A46,"_",Weekly!B46) -> Wipe down Tables @SB_205 | C51: =CONCATENATE(Weekly!F46," / ",Weekly!G46) -> #NAME? | E51: 1 | F51: 1 | G51: k.gunn (48758372) | H51: =LOOKUP(Weekly!E46,Workers!A:A,Workers!B:B) -> Ryan (57174722) | I51: =Weekly!M46 -> #NAME? | J51: en | K51: America/Los_Angeles
A52: task | B52: =CONCATENATE(Weekly!C47," @",Weekly!A47,"_",Weekly!B47) -> Empty Trash Large @SB_Chapel | C52: =CONCATENATE(Weekly!F47," / ",Weekly!G47) -> #NAME? | E52: 1 | F52: 1 | G52: k.gunn (48758372) | H52: =LOOKUP(Weekly!E47,Workers!A:A,Workers!B:B) -> Ryan (57174722) | I52: =Weekly!M47 -> #NAME? | J52: en | K52: America/Los_Angeles
A53: task | B53: =CONCATENATE(Weekly!C48," @",Weekly!A48,"_",Weekly!B48) -> Vacuum Light Traffic @SB_Chapel | C53: =CONCATENATE(Weekly!F48," / ",Weekly!G48) -> #NAME? | E53: 1 | F53: 1 | G53: k.gunn (48758372) | H53: =LOOKUP(Weekly!E48,Workers!A:A,Workers!B:B) -> Ryan (57174722) | I53: =Weekly!M48 -> #NAME? | J53: en | K53: America/Los_Angeles
A54: task | B54: =CONCATENATE(Weekly!C49," @",Weekly!A49,"_",Weekly!B49) -> Empty Trash Small @NB_Children's Lobby | C54: =CONCATENATE(Weekly!F49," / ",Weekly!G49) -> #NAME? | E54: 1 | F54: 1 | G54: k.gunn (48758372) | H54: =LOOKUP(Weekly!E49,Workers!A:A,Workers!B:B) -> Ryan (57174722) | I54: =Weekly!M49 -> #NAME? | J54: en | K54: America/Los_Angeles
A55: task | B55: =CONCATENATE(Weekly!C50," @",Weekly!A50,"_",Weekly!B50) -> Vacuum Light Traffic @NB_Children's Lobby | C55: =CONCATENATE(Weekly!F50," / ",Weekly!G50) -> #NAME? | E55: 1 | F55: 1 | G55: k.gunn (48758372) | H55: =LOOKUP(Weekly!E50,Workers!A:A,Workers!B:B) -> Garrett (57173225) | I55: =Weekly!M50 -> #NAME? | J55: en | K55: America/Los_Angeles
A56: task | B56: =CONCATENATE(Weekly!C51," @",Weekly!A51,"_",Weekly!B51) -> Vacuum Stairs @NB_Children's Lobby | C56: =CONCATENATE(Weekly!F51," / ",Weekly!G51) -> #NAME? | E56: 1 | F56: 1 | G56: k.gunn (48758372) | H56: =LOOKUP(Weekly!E51,Workers!A:A,Workers!B:B) -> Garrett (57173225) | I56: =Weekly!M51 -> #NAME? | J56: en | K56: America/Los_Angeles
A57: task | B57: =CONCATENATE(Weekly!C52," @",Weekly!A52,"_",Weekly!B52) -> Wipe down Stair Rails @NB_Children's Lobby | C57: =CONCATENATE(Weekly!F52," / ",Weekly!G52) -> #NAME? | E57: 1 | F57: 1 | G57: k.gunn (48758372) | H57: =LOOKUP(Weekly!E52,Workers!A:A,Workers!B:B) -> Ryan (57174722) | I57: =Weekly!M52 -> #NAME? | J57: en | K57: America/Los_Angeles
A58: task | B58: =CONCATENATE(Weekly!C53," @",Weekly!A53,"_",Weekly!B53) -> Wipe down Tables @NB_Children's Lobby | C58: =CONCATENATE(Weekly!F53," / ",Weekly!G53) -> #NAME? | E58: 1 | F58: 1 | G58: k.gunn (48758372) | H58: =LOOKUP(Weekly!E53,Workers!A:A,Workers!B:B) -> Ryan (57174722) | I58: =Weekly!M53 -> #NAME? | J58: en | K58: America/Los_Angeles
A59: task | B59: =CONCATENATE(Weekly!C54," @",Weekly!A54,"_",Weekly!B54) -> Empty Trash Large @NB_Coffee | C59: =CONCATENATE(Weekly!F54," / ",Weekly!G54) -> #NAME? | E59: 1 | F59: 1 | G59: k.gunn (48758372) | H59: =LOOKUP(Weekly!E54,Workers!A:A,Workers!B:B) -> Ryan (57174722) | I59: =Weekly!M54 -> #NAME? | J59: en | K59: America/Los_Angeles
... A104: task | B104: =CONCATENATE(Weekly!C99," @",Weekly!A99,"_",Weekly!B99) -> Vacuum Stairs @NB_Gym | C104: =CONCATENATE(Weekly!F99," / ",Weekly!G99) -> #NAME? | E104: 1 | F104: 1 | G104: k.gunn (48758372) | H104: =LOOKUP(Weekly!E99,Workers!A:A,Workers!B:B) -> Garrett (57173225) | I104: =Weekly!M99 -> #NAME? | J104: en | K104: America/Los_Angeles
A105: task | B105: =CONCATENATE(Weekly!C110," @",Weekly!A110,"_",Weekly!B110) -> Empty Trash Large @SB_Kitchen | C105: =CONCATENATE(Weekly!F110," / ",Weekly!G110) -> #NAME? | E105: 1 | F105: 1 | G105: k.gunn (48758372) | H105: =LOOKUP(Weekly!E110,Workers!A:A,Workers!B:B) -> Ryan (57174722) | I105: =Weekly!M110 -> #NAME? | J105: en | K105: America/Los_Angeles
A106: task | B106: =CONCATENATE(Weekly!C111," @",Weekly!A111,"_",Weekly!B111) -> Mop @NB_Kitchen | C106: =CONCATENATE(Weekly!F111," / ",Weekly!G111) -> #NAME? | E106: 1 | F106: 1 | G106: k.gunn (48758372) | H106: =LOOKUP(Weekly!E111,Workers!A:A,Workers!B:B) -> Ryan (57174722) | I106: =Weekly!M111 -> #NAME? | J106: en | K106: America/Los_Angeles
A107: task | B107: =CONCATENATE(Weekly!C112," @",Weekly!A112,"_",Weekly!B112) -> Mop @SB_Kitchen | C107: =CONCATENATE(Weekly!F112," / ",Weekly!G112) -> #NAME? | E107: 1 | F107: 1 | G107: k.gunn (48758372) | H107: =LOOKUP(Weekly!E112,Workers!A:A,Workers!B:B) -> Ryan (57174722) | I107: =Weekly!M112 -> #NAME? | J107: en | K107: America/Los_Angeles
A108: task | B108: =CONCATENATE(Weekly!C113," @",Weekly!A113,"_",Weekly!B113) -> Scrub Sinks @NB_Kitchen | C108: =CONCATENATE(Weekly!F113," / ",Weekly!G113) -> #NAME? | E108: 1 | F108: 1 | G108: k.gunn (48758372) | H108: =LOOKUP(Weekly!E113,Workers!A:A,Workers!B:B) -> Ryan (57174722) | I108: =Weekly!M113 -> #NAME? | J108: en | K108: America/Los_Angeles
A109: task | B109: =CONCATENATE(Weekly!C114," @",Weekly!A114,"_",Weekly!B114) -> Stock Kitchen Supplies @NB_Kitchen | C109: =CONCATENATE(Weekly!F114," / ",Weekly!G114) -> #NAME? | E109: 1 | F109: 1 | G109: k.gunn (48758372) | H109: =LOOKUP(Weekly!E114,Workers!A:A,Workers!B:B) -> Ryan (57174722) | I109: =Weekly!M114 -> #NAME? | J109: en | K109: America/Los_Angeles
A110: task | B110: =CONCATENATE(Weekly!C115," @",Weekly!A115,"_",Weekly!B115) -> Stock Kitchen Supplies @SB_Kitchen | C110: =CONCATENATE(Weekly!F115," / ",Weekly!G115) -> #NAME? | E110: 1 | F110: 1 | G110: k.gunn (48758372) | H110: =LOOKUP(Weekly!E115,Workers!A:A,Workers!B:B) -> Ryan (57174722) | I110: =Weekly!M115 -> #NAME? | J110: en | K110: America/Los_Angeles
A111: task | B111: =CONCATENATE(Weekly!C116," @",Weekly!A116,"_",Weekly!B116) -> Sweep @NB_Kitchen | C111: =CONCATENATE(Weekly!F116," / ",Weekly!G116) -> #NAME? | E111: 1 | F111: 1 | G111: k.gunn (48758372) | H111: =LOOKUP(Weekly!E116,Workers!A:A,Workers!B:B) -> Ryan (57174722) | I111: =Weekly!M116 -> #NAME? | J111: en | K111: America/Los_Angeles
A112: task | B112: =CONCATENATE(Weekly!C117," @",Weekly!A117,"_",Weekly!B117) -> Sweep @SB_Kitchen | C112: =CONCATENATE(Weekly!F117," / ",Weekly!G117) -> #NAME? | E112: 1 | F112: 1 | G112: k.gunn (48758372) | H112: =LOOKUP(Weekly!E117,Workers!A:A,Workers!B:B) -> Ryan (57174722) | I112: =Weekly!M117 -> #NAME? | J112: en | K112: America/Los_Angeles
A113: task | B113: =CONCATENATE(Weekly!C118," @",Weekly!A118,"_",Weekly!B118) -> Wash Towels @NB_Kitchen | C113: =CONCATENATE(Weekly!F118," / ",Weekly!G118) -> #NAME? | E113: 1 | F113: 1 | G113: k.gunn (48758372) | H113: =LOOKUP(Weekly!E118,Workers!A:A,Workers!B:B) -> Ryan (57174722) | I113: =Weekly!M118 -> #NAME? | J113: en | K113: America/Los_Angeles
...

Sheet Todoist In
A1: TYPE | B1: CONTENT | C1: DESCRIPTION | D1: IS_COLLAPSED | E1: PRIORITY | F1: INDENT | G1: AUTHOR | H1: RESPONSIBLE | I1: DATE | J1: DATE_LANG | K1: TIMEZONE | L1: DURATION | M1: DURATION_UNIT | N1: DEADLINE | O1: DEADLINE_LANG
A2: meta | B2: view_style=list
A4: task | B4: Breakdown Sunday @NB_Gym | C4: Wipe down Tables with 2in1 and put away. Empty Coffee Trash. Roll up Rugs and store above Tables. Put Communion Elements in Refrigerator. / Equipment: 2in1 Cleaner, Paper Towel, Trash bag Black | E4: 1 | F4: 1 | G4: Kevin (55885066) | H4: Garrett (57173225) | I4: every Mon | J4: en | K4: America/Los_Angeles
A5: task | B5: Clean Carpets @NB_Hallway_Downstairs | C5: Use Carpet Machine to clean Coffee Stains. / Equipment: Carpet Cleaner, Carpet Cleaner Solution | E5: 1 | F5: 1 | G5: Kevin (55885066) | H5: Ryan (57174722) | I5: every Mon | J5: en | K5: America/Los_Angeles
A6: task | B6: Clean Carpets @NB_Hallway_Upstairs | C6: Use Carpet Machine to clean Coffee Stains. / Equipment: Carpet Cleaner, Carpet Cleaner Solution | E6: 1 | F6: 1 | G6: Kevin (55885066) | H6: Garrett (57173225) | I6: every Fri | J6: en | K6: America/Los_Angeles
A7: task | B7: Clean Carpets @NB_Sanctuary | C7: Use Carpet Machine to clean Coffee Stains. / Equipment: Carpet Cleaner, Carpet Cleaner Solution | E7: 1 | F7: 1 | G7: Kevin (55885066) | H7: Ryan (57174722) | I7: every Mon | J7: en | K7: America/Los_Angeles
A8: task | B8: Disinfect Changing Table @NB_Family_Room | C8: Spray 2in1 on a Paper Towel and wipe down surfaces. / Equipment: 2in1 Cleaner, Paper Towel | E8: 1 | F8: 1 | G8: Kevin (55885066) | H8: Ryan (57174722) | I8: every Wed | J8: en | K8: America/Los_Angeles
A9: task | B9: Disinfect Changing Table @NB_RR_Men_Upstairs | C9: Spray 2in1 on a Paper Towel and wipe down surfaces. / Equipment: 2in1 Cleaner, Paper Towel | E9: 1 | F9: 1 | G9: Kevin (55885066) | H9: Ryan (57174722) | I9: every Mon, Wed, Fri | J9: en | K9: America/Los_Angeles
A10: task | B10: Disinfect Changing Table @NB_RR_Women_Upstairs | C10: Spray 2in1 on a Paper Towel and wipe down surfaces. / Equipment: 2in1 Cleaner, Paper Towel | E10: 1 | F10: 1 | G10: Kevin (55885066) | H10: Ryan (57174722) | I10: every Mon, Wed, Fri | J10: en | K10: America/Los_Angeles
A11: task | B11: Disinfect Water Fountain @NB_Gym | C11: Spray 2in1 on fountain and wipe off with Paper Towels. / Equipment: 2in1 Cleaner, Paper Towel | E11: 1 | F11: 1 | G11: Kevin (55885066) | H11: Ryan (57174722) | I11: every Thu | J11: en | K11: America/Los_Angeles
A12: task | B12: Disinfect Water Fountain @NB_Hallway_Downstairs | C12: Spray 2in1 on fountain and wipe off with Paper Towels. / Equipment: 2in1 Cleaner, Paper Towel | E12: 1 | F12: 1 | G12: Kevin (55885066) | H12: Ryan (57174722) | I12: every Thu | J12: en | K12: America/Los_Angeles
A13: task | B13: Disinfect Water Fountain @NB_Hallway_Upstairs | C13: Spray 2in1 on fountain and wipe off with Paper Towels. / Equipment: 2in1 Cleaner, Paper Towel | E13: 1 | F13: 1 | G13: Kevin (55885066) | H13: Ryan (57174722) | I13: every Fri | J13: en | K13: America/Los_Angeles
A14: task | B14: Empty Diaper Genie @NB_Family_Room | C14: Empty from below. / Equipment: Diaper Genie Refill | E14: 1 | F14: 1 | G14: Kevin (55885066) | H14: Ryan (57174722) | I14: every Mon | J14: en | K14: America/Los_Angeles
A15: task | B15: Empty Diaper Genie @NB_Nursery_Lobby | C15: Empty from below. / Equipment: Diaper Genie Refill | E15: 1 | F15: 1 | G15: Kevin (55885066) | H15: Ryan (57174722) | I15: every Mon, Wed, Fri | J15: en | K15: America/Los_Angeles
... A296: task | B296: Wipe down Toilets @SB_RR_Women_West | C296: Spray Seat, Rim, and Handle with 2in1, wipe with Paper Towel. / Equipment: 2in1 Cleaner, Paper Towel | E296: 1 | F296: 1 | G296: Kevin (55885066) | H296: Cayla (57173614) | I296: every Mon, Tue, Wed, Thu, Fri | J296: en | K296: America/Los_Angeles

Sheet Todoist Changes
A1: =_xludf.CONCAT('Todoist Out'!A4:O4) -> #NAME?

Sheet Workers
A1: Cayla | B1: Cayla (57173614)
A2: Garrett | B2: Garrett (57173225)
A3: Kevin | B3: k.gunn (48758372)
A4: Ryan | B4: Ryan (57174722)
A5: Josh | B5: Josh (58255353)
